<?xml version="1.0" encoding="utf-8"?>
<robot
	name="hola_bot">
<!--chassis-->
	<link
		name="base_link">
		<inertial>
			<origin
				xyz="0 0 0"
				rpy="0 0 0"/>
			<mass
				value="0.49"/>
			<inertia
				ixx="0.00199"
				ixy="0"
        			ixz="0"
        			iyy="0.00199"
        			iyz="0"
        			izz="0.00395"/>
        	</inertial>
        	<visual>
        		<origin
        			xyz="0 0 0"
        			rpy="0 0 1.57"/>
        		<geometry>
        			<mesh
        				filename="package://holo/meshes/base_link.STL"/>
        		</geometry>
        	</visual>
        	<collision>
        		<origin
        			xyz="0 0 -0.1"
        			rpy="0 0 1.57"/>
        		<geometry>
        			<cylinder radius="0.15" length="0.005"/>
        		</geometry>
        	</collision>
        </link>
<!--Front wheel-->
	<!--Front_wheel_link-->
	<link
		name="Front-wheel">
		<inertial>
			<origin
				xyz="0 0 0"
				rpy="0 0 0"/>
			<mass
				value="0.062"/>
			<inertia
				ixx="0.000285"
        			ixy="0"
        			ixz="0"
        			iyy="0.0005198"
        			iyz="0"
        			izz="0.0002851" />
        	</inertial>
        	<visual>
        		<origin
        			xyz="0 -0.01 0"
        			rpy="1.57 0 0"/>
        		<geometry>
        			<mesh
        				filname="package://holo/meshes/wheel.STL"/>
        		</geometry>
        	</visual>
        	<collision>
        		<origin
        			xyz="0 -.01 0"
        			rpy="1.57 0 0"/>
        		<geometry>
        			<cylinder radius="0.03" length="0.02"/>
        		</geometry>
        	</collision>
        </link>
	<!--Front_wheel_joint-->
	<joint
		name="front_joint"
		type="continuous">
		<origin
			xyz="0 0.17483 -0.0335"
      			rpy="0 0 0" />
      		<parent
      			link="base_link" />
      		<child
      			link="front_wheel" />
      		<axis
      			xyz="0 -1 0" />
      		<limit
      			effort="5"
      			velocity="5" />
      	</joint>
<!--left wheel-->
	<!--left_wheel_link-->	
	<link
		name="left-wheel">
		<inertial>
			<origin
				xyz="0.15154 -0.087275 0"
				rpy="${pi/2} 0 0"/>
			<mass
				value="0.062"/>
			<inertia
				ixx="0.000285"
        			ixy="0"
        			ixz="0"
        			iyy="0.0005198"
        			iyz="0"
        			izz="0.0002851" />
        	</inertial>
        	<visual>
        		<origin
        			xyz="0.15154 -0.087275 0"
        			rpy="1.57 0 0"/>
        		<geometry>
        			<mesh
        				filname="package://holo/meshes/wheel.STL"/>
        		</geometry>
        	</visual>
        	<collision>
        		<origin
        			xyz="0.15154 -0.087275 0"
        			rpy="1.57 0 0"/>
        		<geometry>
        			<cylinder radius="0.03" length="0.02"/>
        		</geometry>
        	</collision>
        </link>
	<!--Left_wheel_joint-->
	<joint
		name="left_joint"
		type="continuous">
		<origin
			xyz="00.15154 -0.087275 0"
      			rpy="${pi/2} 0 0" />
      		<parent
      			link="base_link" />
      		<child
      			link="left_wheel" />
      		<axis
      			xyz="0 0 1" />
      		<limit
      			effort="5"
      			velocity="5" />
      	</joint>
<!--right wheel-->
	<!--right_wheel_link-->	
	<link
		name="left-wheel">
		<inertial>
			<origin
				xyz="-0.15154 0.087275 0"
				rpy="${pi/2} 0 0"/>
			<mass
				value="0.062"/>
			<inertia
				ixx="0.000285"
        			ixy="0"
        			ixz="0"
        			iyy="0.0005198"
        			iyz="0"
        			izz="0.0002851" />
        	</inertial>
        	<visual>
        		<origin
        			xyz="-0.15154 0.087275 0"
        			rpy="1.57 0 0"/>
        		<geometry>
        			<mesh
        				filname="package://holo/meshes/wheel.STL"/>
        		</geometry>
        	</visual>
        	<collision>
        		<origin
        			xyz="0.15154 -0.087275 0"
        			rpy="1.57 0 0"/>
        		<geometry>
        			<cylinder radius="0.03" length="0.02"/>
        		</geometry>
        	</collision>
        </link>
	<!--right_wheel_joint-->
	<joint
		name="right_joint"
		type="continuous">
		<origin
			xyz="-0.15154 0.087275 0"
      			rpy="${pi/2} 0 0" />
      		<parent
      			link="base_link" />
      		<child
      			link="right_wheel" />
      		<axis
      			xyz="0 0 -1" />
      		<limit
      			effort="5"
      			velocity="5" />
      	</joint>		
<gazebo>
    <plugin name="object_controller" filename="libgazebo_ros_planar_move.so">
      <commandTopic>cmd_vel</commandTopic>
      <odometryTopic>odom</odometryTopic>
      <odometryFrame>odom</odometryFrame>
      <odometryRate>20.0</odometryRate>
      <robotBaseFrame>base_link</robotBaseFrame>
    </plugin>
  </gazebo>
</robot>
        		
        		
